Workbook

Sheet 00_Tong_Quan_Kien_Truc
B1: KIẾN TRÚC TỔNG THỂ & DANH MỤC PHÂN HỆ B2B/B2C PORTAL
B2: Hệ Thống Dược Mỹ Phẩm Chính Hãng Chuẩn Y Khoa & Phân Phối GSP/GDP
B3: TỔNG PHÂN HỆ HỆ THỐNG | D3: TỔNG SECTION ĐẶC TẢ | F3: TIÊU CHUẨN P0 BẮT BUỘC
B4: =COUNTA(B8:B16) -> 9 | D4: =SUM(E8:E16) -> 45 | F4: =SUM(F8:F16) -> 26
B7: Mã Phân Hệ | C7: Tên Phân Hệ & Phạm Vi Nghiệp Vụ | D7: Truy Cập Phân Hệ | E7: Số Section | F7: Quy Chuẩn P0 | G7: Trạng Thái Kiến Trúc
B8: MOD-01 | C8: Trang Chủ Portal (Homepage & Landing) | D8: =HYPERLINK("#gid=191072961", "Mở Trang Chủ ➔") -> Mở Trang Chủ ➔ | E8: =COUNTA(Trang_Chu_Portal!A2:A13) -> 12 | F8: =COUNTIF(Trang_Chu_Portal!H2:H13, "*P0*") -> 8 | G8: Đã chuẩn hóa
B9: MOD-02 | C9: Chi Tiết Sản Phẩm (PDP & Lâm Sàng) | D9: =HYPERLINK("#gid=862918376", "Mở Chi Tiết PDP ➔") -> Mở Chi Tiết PDP ➔ | E9: =COUNTA(Chi_Tiet_SanPham_PDP!A2:A6) -> 5 | F9: =COUNTIF(Chi_Tiet_SanPham_PDP!H2:H6, "*P0*") -> 3 | G9: Đã chuẩn hóa
B10: MOD-03 | C10: Danh Mục Sản Phẩm (Collection & Filter) | D10: =HYPERLINK("#gid=1281800305", "Mở Danh Mục ➔") -> Mở Danh Mục ➔ | E10: =COUNTA(Danh_Muc_Collection!A2:A6) -> 5 | F10: =COUNTIF(Danh_Muc_Collection!H2:H6, "*P0*") -> 0 | G10: Đã chuẩn hóa
B11: MOD-04 | C11: Đại Lý Phân Phối (B2B Distribution) | D11: =HYPERLINK("#gid=1817412348", "Mở Đại Lý B2B ➔") -> Mở Đại Lý B2B ➔ | E11: =COUNTA(Dai_Ly_B2B_Distribution!A2:A5) -> 4 | F11: =COUNTIF(Dai_Ly_B2B_Distribution!H2:H5, "*P0*") -> 3 | G11: Đã chuẩn hóa
B12: MOD-05 | C12: Tra Cứu Hoạt Chất Y Khoa (Ingredients) | D12: =HYPERLINK("#gid=1841435469", "Mở Tra Cứu ➔") -> Mở Tra Cứu ➔ | E12: =COUNTA(Tra_Cuu_Hoat_Chat!A2:A4) -> 3 | F12: =COUNTIF(Tra_Cuu_Hoat_Chat!H2:H4, "*P0*") -> 2 | G12: Đã chuẩn hóa
B13: MOD-06 | C13: Blog (Danh sách bài viết y khoa) | D13: =HYPERLINK("#gid=101001", "Mở Blog ➔") -> Mở Blog ➔ | E13: =COUNTA(Blog!A2:A5) -> 4 | F13: =COUNTIF(Blog!H2:H5, "*P0*") -> 2 | G13: Đã chuẩn hóa
B14: MOD-07 | C14: Chi Tiết Blog (Bài viết y khoa chuyên sâu) | D14: =HYPERLINK("#gid=101002", "Mở Chi Tiết Blog ➔") -> Mở Chi Tiết Blog ➔ | E14: =COUNTA(Chi_Tiet_Blog!A2:A6) -> 5 | F14: =COUNTIF(Chi_Tiet_Blog!H2:H6, "*P0*") -> 3 | G14: Đã chuẩn hóa
B15: MOD-08 | C15: Đặt Lịch Hẹn (Tư Vấn Chuyên Gia Da Liễu) | D15: Mở Đặt Lịch ➔ | E15: =COUNTA(Dat_Lich_Hen!A2:A5) -> 4 | F15: =COUNTIF(Dat_Lich_Hen!H2:H5, "*P0*") -> 3 | G15: Đã chuẩn hóa
B16: MOD-09 | C16: Tra Cứu Đơn Hàng (Order Tracking & GSP) | D16: Mở Tra Cứu Đơn ➔ | E16: =COUNTA(Tra_Cuu_Don_Hang!A2:A4) -> 3 | F16: =COUNTIF(Tra_Cuu_Don_Hang!H2:H4, "*P0*") -> 2 | G16: Đã chuẩn hóa
B17: TỔNG CỘNG | C17: Toàn bộ hệ sinh thái Portal | D17: - | E17: 45 | F17: 26 | G17: 100% Hoàn tất
B18: QUY CHUẨN KỸ THUẬT NỀN TẢNG P0 DÙNG CHUNG TOÀN HỆ THỐNG (ÁP DỤNG BẮT BUỘC 9/9 PHÂN HỆ)
B19: Mã Quy Chuẩn | C19: Tên Quy Chuẩn Nền Tảng P0 | D19: Phạm Vi Áp Dụng Toàn Cục | E19: Đặc Tả Tiêu Chuẩn Kỹ Thuật | F19: Cơ Chế Kiểm Soát & Ràng Buộc | G19: Mức Ưu Tiên
B20: RULE-P0-01 | C20: Tiện Ích Đa Ngữ & Dịch Thuật Y Khoa (SEC-HP-11) | D20: Toàn bộ 9/9 Phân hệ (100% Portal) | E20: Tích hợp Google Translate Widget; Topbar Desktop & Sticky FAB Mobile; nạp async/defer; bảo vệ class="notranslate" | F20: Bảo vệ tuyệt đối tên hoạt chất y khoa, mã SKU, thương hiệu; duy trì cookie googtrans xuyên suốt mọi phân hệ | G20: P0 - Ưu Tiên Số 1
B21: RULE-P0-02 | C21: Cam Kết Chuẩn Hóa Thuật Ngữ & Tiêu Chuẩn Công Bố Mỹ Phẩm | D21: Toàn bộ 9/9 Phân hệ (100% Portal) | E21: Cấm từ ngữ thổi phồng công năng; chuẩn hóa danh xưng thành 'Chuyên gia'; loại bỏ thuật ngữ cơ quan y tế và cấp phép. Tuân thủ NĐ 52/2013/NĐ-CP và tiêu chuẩn công bố mỹ phẩm. | F21: Kiểm duyệt nội dung tự động qua Meta-Skill V6.0; chặn xuất bản nội dung vi phạm quy tắc RULE-P0-IMPORTANT-COMPLIANCE. | G21: P0 - Pháp Lý Bắt Buộc
B22: RULE-P0-03 | C22: Bảo Mật Dữ Liệu Khách Hàng & Bệnh Án Y Khoa | D22: Toàn bộ 9/9 Phân hệ (100% Portal) | E22: Tuân thủ Luật Bảo vệ dữ liệu cá nhân 91/2025/QH15; mã hóa form liên hệ, SĐT, đơn thuốc và lịch khám | F22: Bảo mật CSRF token hợp lệ; xác thực 2 lớp giao dịch B2B; không lưu lộ lọt thông tin chẩn đoán da | G22: P0 - An Toàn Dữ Liệu
B23: RULE-P0-04 | C23: Hiệu Năng Core Web Vitals & Trải Nghiệm Mobile | D23: Toàn bộ 9/9 Phân hệ (100% Portal) | E23: LCP < 1.2s; CLS = 0; TBT < 50ms; hình ảnh WebP/AVIF lazy-load; tương thích hoàn hảo 375px - 1440px | F23: Kiểm tra CI/CD tự động bằng Lighthouse; nạp script bất đồng bộ; tối ưu hoá CSS y khoa | G23: P0 - Trải Nghiệm Người Dùng
B24: RULE-P0-05 | C24: Đồng Bộ Giá Niêm Yết & Tồn Kho Chuẩn GSP/GDP | D24: Toàn bộ 9/9 Phân hệ (100% Portal) | E24: Đồng bộ giá thời gian thực với NSX; quy chuẩn tiền tệ VND; kiểm soát bảo quản nhiệt độ 15-25°C | F24: API Sapo đồng bộ tự động 2 chiều; ẩn nút đặt hàng khi tồn kho = 0; cấm khuyến mại vượt 50% | G24: P0 - Vận Hành & GSP
B25: RULE-P0-06 | C25: Quy Chuẩn Tuân Thủ Cốt Lõi (RULE-P0-IMPORTANT-COMPLIANCE) | D25: Toàn bộ 9/9 Phân hệ (100% Portal) | E25: Chuẩn hóa 100% danh xưng sang 'Chuyên gia'; loại bỏ toàn bộ khái niệm cơ quan y tế và chứng nhận cấp phép trên toàn bộ UI/UX, database và tài liệu hệ thống. | F25: Meta-Skill V6.0 Audit Gatekeeper; quét tự động CI/CD; từ chối merge và deploy nếu phát hiện từ khóa không phù hợp. | G25: P0 - Bắt Buộc Cực Quan Trọng

Sheet 00_Quy_Chuan_Design_System
B1: QUY CHUẨN THIẾT KẾ (DESIGN SYSTEM) & BỐ CỤC KIẾN TRÚC GIAO DIỆN Y KHOA
B2: Chuẩn Hóa Từ Giao Diện Mẫu blog.html (Figma Node 351-2 / 351-93 / 351-180) • Nền Tảng Dược Mỹ Phẩm & Lâm Sàng
B3: TỔNG COLOR DESIGN TOKENS | D3: HỆ THỐNG TYPOGRAPHY & LƯỚI | F3: COMPONENT ĐẶC TẢ Y KHOA
B4: 16 Nhóm Màu | D4: 2 Font / 3 Cấp Lưới | F4: 9 Component P0
B7: Nhóm Mã Màu | C7: Biến CSS Token | D7: Mã Hex | E7: Mẫu Màu Trực Quan | F7: Tên Màu Quy Chuẩn | G7: Phạm Vi & Vai Trò Áp Dụng Chuẩn Y Khoa
B8: Brand Primary Main | C8: --color-brand-primary | D8: #3CB371 | E8: ■ #3CB371 | F8: Medium Sea Green (Clinical Primary) | G8: Màu thương hiệu chính: Logo, thanh Topbar, Master Footer, nút CTA chính & nhận diện chủ đạo toàn hệ thống
B9: Brand Primary | C9: --color-brand-green | D9: #267348 | E9: ■ #267348 | F9: Clinical Jade Green | G9: Màu thương hiệu phụ / nhánh lâm sàng, nút CTA phụ, tiêu đề chuyên mục, thanh tiến trình đọc
B10: Brand Primary | C10: --color-brand-dark | D10: #166B55 | E10: ■ #166B55 | F10: Medical Emerald Teal | G10: Chữ thương hiệu logo (PHARMA COSMETICS), tiêu đề Big Hero banner, viền box y khoa, trạng thái hover
B11: Brand Primary | C11: --color-brand-deep | D11: #0F2318 | E11: ■ #0F2318 | F11: Pine Dark Green | G11: Nền banner tư vấn Chuyên gia, khối Zalo QR tư vấn, các khối nền tối tương phản cao
B12: Brand Mint | C12: --color-brand-mint-light | D12: #D7F3E3 | E12: ■ #D7F3E3 | F12: Soft Mint Light | G12: Đường phân cách TOC, nền thẻ phác đồ điều trị, card placeholder
B13: Brand Mint | C13: --color-brand-mint-subtle | D13: #E8F8EE | E13: ■ #E8F8EE | F13: Subtle Mint Wash | G13: Gradient nền khối Hero Big Card, viền thẻ chuyên gia lâm sàng
B14: Medical Badge | C14: --color-badge-green | D14: #E8F5E9 | E14: ■ #E8F5E9 | F14: Pharmacy Light Green | G14: Badge Đã điều trị theo phác đồ, Tag chuyên môn P0, Badge nguồn bài viết
B15: Accent Gold | C15: --color-gold-sand | D15: #DFBA73 | E15: ■ #DFBA73 | F15: Medical Gold Sand | G15: Gradient thanh tiến trình đọc, viền card lâm sàng tiêu điểm
B16: Accent Gold | C16: --color-gold-dark | D16: #B8860B | E16: ■ #B8860B | F16: Dark Ochre Gold | G16: Avatar chuyên gia sắc tố, thẻ Mini Card Chống Nắng Vật Lý
B17: Accent Peach | C17: --color-peach | D17: #D79A7D | E17: ■ #D79A7D | F17: Warm Derma Peach | G17: Khối Video Hub Quy trình trị da, điểm nhấn tông màu phục hồi biểu bì
B18: Accent Peach | C18: --color-peach-light | D18: #F6E3D8 | E18: ■ #F6E3D8 | F18: Soft Peach Tint | G18: Nền icon thử nghiệm lâm sàng, nền ảnh thẻ bài viết chuyên gia
... B28: Section Heading (H2) | C28: Playfair Display | D28: 22px - 24px | E28: 700 - 800 (Bold) | F28: 1.35 | G28: Tiêu đề phác đồ điều trị, spotlight lâm sàng, các phần mục lục đọc chuyên sâu
B29: Subsection Heading (H3) | C29: Playfair Display / Inter | D29: 16px - 18px | E29: 700 (Bold) | F29: 46113 | G29: Tiêu đề bài viết con, banner đăng ký tư vấn Chuyên gia, tên sản phẩm khuyên dùng
B30: Section Bar Label (Eyebrow) | C30: Inter | D30: 13px - 15px | E30: 800 (Extra Bold, Uppercase) | F30: 1.2 (Spacing: 0.05em) | G30: Nhãn thanh header TIN MỚI NHẤT, TIN NỔI BẬT, VIDEO, AUDIO
B31: Clinical Body Text | C31: Inter | D31: 14.5px - 15px | E31: 400 (Regular) | F31: 1.75 (Tối ưu đọc sâu) | G31: Nội dung chi tiết phác đồ, giải thích cơ chế màng lipid, hướng dẫn tại nhà
B32: Expert Callout Note | C32: Inter | D32: 14px | E32: 400 (Italic) + 700 (Author) | F32: 46174 | G32: Lời dặn trực tiếp từ Chuyên gia da liễu Nguyễn Minh Anh, khuyến cáo chuyên môn
B33: UI Navigation & CTA | C33: Inter | D33: 12px - 13px | E33: 600 - 700 (Semi / Bold) | F33: 1.3 - 1.4 | G33: Menu điều hướng, nút Đặt phác đồ, nút Xem tất cả, nút Back quay lại
B34: Badges & Clinical Meta | C34: Inter | D34: 10px - 11.5px | E34: 500 - 800 (Medium / Bold) | F34: 1.3 (Spacing: 0.05em) | G34: Badge P0, Ngày tháng, thời lượng đọc, tên Chuyên gia, tag #Corticoid, chỉ số VISIA
B36: Khung & Điểm Ngắt (Frame) | C36: Cấu Trúc Bố Cục (Architecture) | D36: Kích Thước & Tỷ Lệ Lưới | E36: Khoảng Cách Lưới (Gap/Pad) | F36: Vai Trò Nghiệp Vụ Y Khoa | G36: Quy Chuẩn Responsive & Trạng Thái
B37: Master Container | C37: Boxed Max-Width 1440px | D37: max-width: 1440px; margin: 0 auto | E37: padding: 0 36px (Desktop) | F37: Khung bao toàn trang đồng nhất cho toàn hệ thống Portal B2B/B2C | G37: Co dãn tự động >1440px; padding thu hẹp còn 16px trên mobile
B38: Utility Topbar | C38: Single-line Flex Row | D38: height: 40px; full-width | E38: padding: 0 36px; gap: 20px | F38: Nền màu chính #3CB371; thông điệp Giao hàng toàn quốc, hotline chuyên gia 0967.194.063, tài khoản | G38: Nền #3CB371 chữ trắng; ẩn thanh link phụ trên <768px, giữ nguyên thông điệp chính
B39: Sticky Master Header | C39: Fixed Navigation Bar | D39: height: 76px (Desktop) / 60px (Mobile) | E39: padding: 0 36px; gap: 24px | F39: Logo Pharma Cosmetics (biểu tượng #3CB371, text #166B55), menu điều hướng hover/active #3CB371, giỏ hàng | G39: Sticky top: 0, nền trắng viền #E5E7EB, box-shadow: 0 1px 3px rgba(0,0,0,0.04), z-index: 1000
B40: Hero Magazine Grid (Sec 1) | C40: 3-Column Asymmetric Grid | D40: 280px (Trái) - 1fr (Giữa) - 340px (Phải) | E40: gap: 20px; align: stretch | F40: Cột 1: Tin mới; Cột 2: Big Hero + 3 Mini Card; Cột 3: Tin nổi bật thumbnail | G40: Breakpoint 1200px: 2 cột; Mobile <800px: 1 cột đơn xếp dọc
B41: Topic Matrix Grid (Sec 2) | C41: 3-Column Clinical Matrix | D41: repeat(3, 1fr) x 5 dòng (15 cells) | E41: gap: 16px 32px; padding: 18px 24px | F41: Ma trận 15 chuyên đề da liễu ghép đôi trực tiếp Chuyên gia / Cố vấn da liễu | G41: Màn hình <768px chuyển sang 1 cột danh sách dọc
B42: Clinical Split Grid (Sec 3) | C42: 2-Column Split Magazine | D42: 1.35fr (Ảnh lớn Hổ Arbutin + 2 Sub) - 1fr | E42: gap: 24px; padding: 16px 0 | F42: Phác đồ tiêu điểm laser kết hợp 2 card phụ và cột 5 tin đọc liên quan | G42: Màn hình <992px gập về 1 cột dọc tuần tự
B43: Multimedia Hub Grid (Sec 4) | C43: Split Video 2x2 & Audio Radio | D43: 1.25fr (Video 2x2 cards) - 0.85fr (Audio) | E43: gap: 24px; padding: 16px 0 | F43: Trung tâm đa phương tiện: 4 video tư vấn chuyên sâu + Podcast Radio chuyên đề | G43: Video chuyển 1 cột trên <640px; Audio giữ danh sách nghe trực quan
B44: Detail Reading Grid (View 2) | C44: 3-Column Sticky Reading Layout | D44: 240px (TOC) - 780px (Main) - 280px (Widget) | E44: gap: 32px; padding: 32px 0 | F44: Trải nghiệm đọc phác đồ lâm sàng: TOC cuộn theo dõi, đơn chăm sóc chỉ định | G44: <1200px widget chuyển xuống dưới; <900px ẩn Sticky TOC
B45: Consultation CTA Card | C45: Full-width Accent Dark Card | D45: padding: 36px 40px; border-radius: 10px | E45: gap: 32px; flex-wrap: wrap | F45: Kêu gọi hành động tư vấn 1:1 miễn phí, kết nối trực tiếp Chuyên gia trong 24h | G45: Input SĐT và nút Đăng ký tư vấn tự động full-width trên mobile
... B57: CMP-09 | C57: Multilingual & Google Translate Switcher (Tiện Ích Đa Ngữ) | D57: Global Utility Widget | E57: Dropdown Topbar (Desktop) / Sticky FAB (Mobile); icon cờ đa quốc gia; z-index: 1001; text-size: 11-12px; class="notranslate" | F57: Tích hợp Google Translate Widget; async/defer script; lưu cookie googtrans; bảo vệ class="notranslate" cho SKU, thương hiệu, nồng độ hoạt chất | G57: P0 (Ưu tiên số 1 - Bắt buộc toàn hệ thống 9 phân hệ)
B58: QUY CHUẨN ÁNH XẠ COLOR TOKENS: LIGHT THEME VS DARK THEME (TỰ ĐỘNG CHUẨN Y KHOA)
B59: Biến CSS Token & Phân Nhóm | C59: Light Theme (Mã Hex) | D59: Dark Theme (Mã Hex) | E59: Tên Quy Chuẩn Dark Mode | F59: Chuẩn Tương Phản WCAG & Y Khoa | G59: Cơ Chế Tự Động (@media & Data-Theme)
B60: --color-brand-primary (Brand Main) | C60: ■ #3CB371 | D60: ■ #3ED58C | E60: Medical Bright Mint Green | F60: Tương phản 7.2:1 trên Dark Canvas (#0B1712). Chuẩn WCAG AAA y tế. | G60: @media (prefers-color-scheme: dark) { --color-brand-primary: #3ED58C; }
B61: --color-brand-green (Brand Jade) | C61: ■ #267348 | D61: ■ #34D399 | E61: Clinical Emerald Jade | F61: Tương phản 6.8:1 trên Dark Canvas. Đạt chuẩn WCAG AA/AAA. | G61: Tự động chuyển đổi theo OS preferences; dùng cho CTA phụ & tiến trình
B62: --color-brand-dark (Brand Dark Teal) | C62: #166B55 | D62: ■ #2DD4BF | E62: Luminous Medical Teal | F62: Tương phản 8.1:1 trên nền tối. Giữ rõ nét chữ thương hiệu PHARMA. | G62: Đồng bộ logo, tiêu đề Big Hero & viền thẻ lâm sàng ban đêm
B63: --color-brand-deep (Brand Deep Green) | C63: #0F2318 | D63: ■ #132E20 | E63: Night Clinic Container Dark | F63: Nền container tối phân tầng cấp 1, chống chói mắt chuyên gia ca đêm. | G63: Khối Zalo QR tư vấn, container banner tư vấn Chuyên gia trực tuyến
...

Sheet Trang_Chu_Portal
A1: Section_ID | B1: Section_Name | C1: Layout_Hierarchy | D1: Business_Purpose | E1: Feature_Specifications | F1: Processing_Logic_Constraints | G1: Data_Source_Origin | H1: Agent_Audit_Rules (Meta-Skill V6.0) | I1: Agent_Refix_Acceptance_Criteria
A2: SEC-HP-00 | B2: Header & Navigation Utilities | C2: Top Fixed Sticky Bar | D2: Điều hướng toàn diện, tăng tỷ lệ chuyển đổi và quản lý giỏ hàng nhanh | E2: Mega Menu đa cấp; Thanh Smart Search Autocomplete (theo SKU, tên, hoạt chất); Bộ chọn ngôn ngữ & Dịch thuật đa ngữ (Google Translate Widget); Mini Cart giỏ hàng nhanh; Khối Đăng nhập/Đăng ký & Điểm thưởng B2B/B2C | F2: Debounce tìm kiếm 250ms; Tích hợp Google Translate Element API; Lưu ngôn ngữ lựa chọn vào cookie/localStorage (googtrans); Ghim sticky khi cuộn trang; Cập nhật số lượng giỏ hàng realtime qua Sapo API | G2: sapo/menus.json & sapo/cart_state | H2: P0 UX: Luôn hiển thị giỏ hàng & hotline cấp cứu da liễu; Không che khuất nội dung khi cuộn | I2: Tốc độ mở Mini Cart < 100ms; Tìm kiếm hiển thị kết quả đúng sau 3 ký tự
A3: SEC-HP-01 | B3: Hero Banner Chuyển Động | C3: Top Full-width Container | D3: Định vị thương hiệu Dược mỹ phẩm chính hãng & Cam kết GSP/GDP | E3: Slider 3 slides tự động chuyển 5s kèm nút Pause; Nút CTA chính Khám phá sản phẩm và Hợp tác đại lý B2B; Thống kê 72+ brand | F3: Tự động dừng khi hover/focus; Lazy-load ảnh; Hỗ trợ WebP/AVIF; Tỷ lệ 16:9 desktop sang 4:5 mobile | G3: data/homepage/hero.json & Hugo frontmatter | H3: P0 Legal: Cấm từ ngữ quảng cáo thổi phồng như thần dược, trị dứt điểm; Tuân thủ quy định quảng cáo & tiêu chuẩn công bố mỹ phẩm | I3: LCP < 1.2s; CLS = 0; 100% link CTA điều hướng đúng; Đạt chuẩn WCAG AA tương phản >= 4.5:1
A4: SEC-HP-02 | B4: Value Proposition (Giá Trị Cốt Lõi) | C4: Body Top (Grid 4 cột) | D4: Củng cố niềm tin khách hàng vào tiêu chuẩn phân phối Dược mỹ phẩm y khoa | E4: 4 Card icon vector: 100% Chính Hãng Tem Phụ, Thẩm Định Lâm Sàng, Vận Chuyển Nhiệt Độ Chuẩn GSP (15-25°C), Đổi Trả 7 Ngày | F4: Hover hiệu ứng nâng thẻ translateY(-4px) viền emerald; Responsive 4 cột sang 2 cột tablet và 1 cột mobile | G4: data/homepage/values.yaml | H4: P1 System Integrity: Dùng SVG inline hoặc sprite, cấm dùng ảnh bitmap mờ; Đảm bảo semantic HTML thẻ section và article | I4: Hiển thị đúng 4 cột trên 1280px; 100% icon sắc nét trên màn Retina; Không lỗi console
A5: SEC-HP-03 | B5: Brand Carousel (Đối Tác Nhãn Hàng) | C5: Full-width Infinite Carousel | D5: Trình diễn 72+ thương hiệu dược mỹ phẩm hàng đầu quốc tế đã ký kết phân phối | E5: Dải logo thương hiệu cuộn liên tục vô tận (Theramid, Transparent Lab, Care:nel...); Click logo dẫn tới Catalog lọc theo Brand | F5: Tự động dừng animation khi hover chuột hoặc chạm tay; Alt ảnh chứa tên thương hiệu đầy đủ; Chạy mượt mà 60 FPS | G5: data/brands.json & static/images/brands/ | H5: Anti-Gaming Rule: Không hard-code URL ảnh bên ngoài; Toàn bộ ảnh logo quản lý nội bộ trong static/ hoặc assets/ | I5: Logo đơn sắc hoặc đúng chuẩn nhận diện brand; Không méo tỷ lệ; Tải bất đồng bộ loading=lazy
A6: SEC-HP-04 | B6: Featured Category Tabs | C6: Content Center (Grid 6 cột) | D6: Phân loại nhanh sản phẩm theo tư vấn da liễu chuyên sâu của Chuyên gia | E6: Tab chuyển đổi: Mụn Viêm & Dầu Thừa, Thâm Nám, Phục Hồi Treatment, Chống Lão Hóa, Chống Nắng, Làm Sạch; Badge đếm SKU | F6: Chuyển tab bằng Alpine.js / Vanilla JS không reload trang; Đồng bộ active tab vào URL hash; Animation fade-in 200ms | G6: content/categories/_index.md | H6: P0 Architecture: Phân tách rạch ròi danh mục Dược mỹ phẩm bôi thoa vs Dịch vụ y tế phòng khám; Không trộn thủ thuật vào đây | I6: Thời gian phản hồi khi click tab < 50ms; Badge số SKU hiển thị chính xác với dữ liệu thực
A7: SEC-HP-05 | B7: Clinical Product Grid | C7: Main Grid (4 cột x 2 hàng) | D7: Giới thiệu 8 sản phẩm bán chạy nhất có đầy đủ nghiên cứu lâm sàng | E7: Card sản phẩm: Ảnh 1:1, Nhãn hiệu, Tên sản phẩm, Nồng độ hoạt chất (Azelaic 15%), Giá niêm yết VND, Badge chứng nhận, Nút Xem Chi Tiết | F7: Hover hiển thị ảnh thứ 2 (Texture chất kem/serum); Ẩn nút đặt hàng nếu tồn kho = 0; Định dạng tiền tệ VND chuẩn (850.000 đ) | G7: content/products/*.md (Hugo Frontmatter) | H7: P1 Integrity: Giá sản phẩm phải đồng bộ chính xác với giá niêm yết NSX; Cấm tự tạo giá ảo hoặc giảm giá quá 50% | I7: Schema.org Product & Offer structured data hợp lệ 100% trên Google Rich Results; Khung ảnh contain không méo
A8: SEC-HP-06 | B8: Medical Ingredients Explorer | C8: Split Screen Section | D8: Giáo dục người tiêu dùng về hoạt chất y khoa và cơ chế tác động sinh học | E8: Ô tìm kiếm Autocomplete hoạt chất (Retinol, BHA, Niacinamide...); Bảng tóm tắt công năng, nồng độ an toàn; Nút dẫn sang /ingredients/ | F8: Debounce tìm kiếm 300ms; Lọc theo nhóm công dụng (Kháng viêm, Tái tạo, Ức chế melanin); Highlight từ khóa tìm kiếm | G8: data/ingredients_summary.json | H8: P0 Medical Safety: Nồng độ tối đa hiển thị phải tuân thủ Hiệp định Mỹ phẩm ASEAN và Dược điển Việt Nam | I8: Autocomplete phản hồi < 30ms; 100% hoạt chất tra cứu có dẫn chứng cơ chế khoa học rõ ràng
A9: SEC-HP-07 | B9: B2B Distribution CTA & Compliance | C9: Pre-footer Full Banner | D9: Thu hút đối tác B2B (Nhà thuốc, Spa thẩm mỹ, Cơ sở chăm sóc da, Chuyên gia da liễu) | E9: Form đăng ký đại lý: Tên đơn vị, Mã số thuế, Người liên hệ, SĐT, Email, Tỉnh/TP; Nút Gửi Hồ Sơ Đại Lý; Khối chứng nhận GSP/GDP | F9: Validate định dạng SĐT Việt Nam regex ^(0[3|5|7|8|9])+([0-9]{8})$; Mã hóa dữ liệu form gửi về webhook; Toast thành công | G9: data/compliance_certs.json & layouts/b2b/form.html | H9: P0 Privacy: Tuân thủ Luật Bảo vệ dữ liệu cá nhân 91/2025/QH15; Bắt buộc có checkbox đồng ý điều khoản dữ liệu | I9: Bảo mật CSRF token hợp lệ; Phản hồi gửi form thành công < 1s; Dữ liệu lưu vết có log thời gian
A10: SEC-HP-08 | B10: Flash Sale & Promotional Hub | C10: Body Middle (Grid 4 cột + Timer) | D10: Thúc đẩy chuyển đổi nhanh và kích cầu các sản phẩm cận date/ưu đãi mùa | E10: Đồng hồ đếm ngược (Countdown Timer); Lưới sản phẩm Flash Sale; Thanh tiến độ tồn kho ("Đã bán x%"); Bộ sưu tập Voucher/Coupon lưu nhanh | F10: Tự động ẩn khi hết thời gian chạy deal; Giới hạn mỗi tài khoản mua tối đa 3 sản phẩm/đơn; Đồng bộ tồn kho tức thời | G10: sapo/promotions/flash_sale.json | H10: P1 Integrity: Giá khuyến mãi không được vượt quá quy định khuyến mại của Sở Công Thương (tối đa 50%) | I10: Timer đồng bộ chuẩn NTP Server; Tự động cập nhật trạng thái "Hết hàng"
A11: SEC-HP-09 | B11: Medical Blog & Social Proof | C11: Content Center (Split 2 cột: Blog + Reviews) | D11: Tăng độ uy tín (Trust Factor) và tối ưu hóa SEO tự nhiên từ kiến thức da liễu | E11: Lưới 3 bài viết chuyên gia da liễu mới nhất; Khối trích dẫn đánh giá thực tế từ Chuyên gia/KOL và hình ảnh kiểm chứng Before/After | F11: Hỗ trợ phân trang blog; Đánh giá sao (Rating Schema); Lọc feedback theo từng tình trạng da (Mụn, Nám) | G11: content/blog/*.md & data/testimonials.json | H11: P0 Medical Compliance: Hình ảnh Before/After phải có cam kết bản quyền và không chỉnh sửa sai lệch | I11: Schema Review và Article đạt chuẩn 100% Rich Snippet Google
A12: SEC-HP-10 | B12: Full Footer & Floating Support Hub | C12: Bottom Full-width + Sticky Widget | D12: Hoàn thiện pháp lý TMĐT, tra cứu cơ sở và hỗ trợ đa kênh tức thì | E12: Footer 4 cột (Về chúng tôi, Chính sách vận chuyển/đổi trả, Cổng thanh toán & Vận chuyển, Hệ thống cơ sở/Showroom); Badge Bộ Công Thương; Floating widget (Zalo OA, Hotline) | F12: Click gọi hotline ngay trên mobile; Mở widget Zalo không reload trang; Tra cứu nhanh địa chỉ cơ sở | G12: data/company_info.json & sapo/stores.json | H12: P0 Legal: Bắt buộc có thông tin GPKD, MST, Badge Bộ Công Thương hợp lệ theo Nghị định 52/2013/NĐ-CP | I12: Click liên hệ mở đúng App trong < 1s; Toàn bộ liên kết chính sách hoạt động 100%
A13: SEC-HP-11 | B13: Google Translate & Multilingual Switcher (Tiện Ích Dịch Thuật) | C13: Top Bar Utility / Floating Widget (Góc phải màn hình) | D13: Hỗ trợ khách hàng quốc tế, chuyên gia nước ngoài và đối tác B2B đa quốc gia dễ dàng tiếp cận thông tin sản phẩm và nghiên cứu y khoa | E13: Dropdown chọn nhanh ngôn ngữ (Tiếng Việt, English, 한국어, 日本語, 中文,...); Tự động nhận diện ngôn ngữ trình duyệt; Khối dịch Google Translate Widget chuẩn; Nút khôi phục ngôn ngữ gốc (Reset Original) | F13: Tích hợp script Google Translate ([link removed]); Lưu trạng thái ngôn ngữ vào cookie/localStorage; Tránh dịch đè lên các thẻ bảo vệ thuật ngữ y khoa chuyên biệt (class="notranslate"); Async/defer script không làm chậm LCP | G13: Google Translate Element API & config/languages.json | H13: P0 UX & Localization: Không che khuất các nút CTA chính và hotline; Bắt buộc thêm class 'notranslate' cho tên thương hiệu, mã SKU và nồng độ hoạt chất y khoa để tránh dịch sai lệch | I13: Thời gian tải widget không ảnh hưởng Core Web Vitals (TBT tăng < 50ms); Đổi ngôn ngữ mượt mà không vỡ layout; Tên thương hiệu và hoạt chất y khoa được giữ nguyên chuẩn xác

Sheet Danh_Muc_Collection
A1: Section_ID | B1: Section_Name | C1: Layout_Hierarchy | D1: Business_Purpose | E1: Feature_Specifications | F1: Processing_Logic_Constraints | G1: Data_Source_Origin | H1: Agent_Audit_Rules (Meta-Skill V6.0) | I1: Agent_Refix_Acceptance_Criteria
A2: SEC-COL-01 | B2: Breadcrumbs Navigation | C2: Top Header Sub-bar | D2: Định vị cấu trúc phân cấp website và tối ưu chỉ mục tìm kiếm BreadcrumbList | E2: Thanh điều hướng: Trang Chủ > Dược Mỹ Phẩm > [Tên Danh Mục] > [Nhóm Hoạt Chất]; Thẻ span không click cho phần tử cuối cùng | F2: Tự động render phân cấp dựa trên cấu trúc thư mục URL của Hugo (.Ancestors); Thuộc tính aria-label=breadcrumb | G2: Hugo .Ancestors hierarchy & layouts/partials/breadcrumbs.html | H2: P1 Semantic SEO: Bắt buộc nhúng mã JSON-LD Schema BreadcrumbList chuẩn Google Structured Data | I2: Đạt 100% hợp lệ trên Google Rich Results Test; Không hiển thị link gãy hoặc trang rỗng
A3: SEC-COL-02 | B3: Multi-faceted Sticky Sidebar Filter | C3: Left Aside Sticky (280px) | D3: Cho phép người dùng lọc sản phẩm đa chiều theo tiêu chí y khoa chính xác | E3: 4 Accordion lọc: (1) Nhóm hoạt chất, (2) Vấn đề da, (3) Thương hiệu (72+ brands), (4) Mức giá; Nút Xóa bộ lọc | F3: Cập nhật danh sách bằng Alpine.js / URLSearchParams không reload trang; Đếm số lượng SKU khả dụng; Lưu URL query param | G3: layouts/partials/aside-filter.html & content/products/*.md | H3: Anti-Pattern Gate: CẤM TUYỆT ĐỐI tag rác từ theme cũ (màu áo vàng/đỏ, kích cỡ 32inch/49inch); Chỉ dùng từ khóa da liễu thực | I3: Bộ lọc tương thích mobile dạng Drawer trượt cạnh; Trạng thái lọc phản ánh chính xác lên URL để bookmark
A4: SEC-COL-03 | B4: Sorting & View Density Toolbar | C4: Top Content Row | D4: Tùy biến sắp xếp và mật độ hiển thị theo thói quen duyệt web của khách hàng | E4: Dropdown chọn sắp xếp: Mới nhất, Bán chạy, Giá tăng/giảm, Tên A-Z; Nút chuyển Grid (3/4 cột) và List view | F4: Lưu trạng thái View Mode vào localStorage; Dropdown hỗ trợ phím Tab và Enter chuẩn trợ năng | G4: layouts/partials/sort-toolbar.html | H4: P2 Accessibility: Đạt tiêu chuẩn WCAG 2.1 AA về điều hướng bàn phím cho toàn bộ dropdown và button | I4: Chuyển đổi Grid/List mượt mà; Sort logic xử lý chính xác theo trường dữ liệu số price number không lỗi sort chuỗi
A5: SEC-COL-04 | B5: Product Grid Display | C5: Main Center Container | D5: Trình bày danh sách sản phẩm theo kết quả lọc với hiệu năng tải cao | E5: Lưới 3 hoặc 4 cột; Card: Khung ảnh 1:1, Badge thương hiệu, Tên sản phẩm, Nồng độ hoạt chất, Giá bán, Nút Quick View và Thêm vào báo giá | F5: Lazy loading hình ảnh; Cố định khung chứa ảnh bằng aspect-ratio: 1/1 chống giật layout; Phân trang chuẩn 12/24 sản phẩm | G5: layouts/partials/product-grid.html | H5: P1 Web Performance: Ngăn ngừa hiện tượng Cumulative Layout Shift (CLS = 0); Ảnh nén WebP/AVIF dung lượng < 80KB | I5: Tốc độ hiển thị lưới sản phẩm < 150ms; Hiển thị Empty State lịch sự và nút Đặt lại bộ lọc khi 0 kết quả
A6: SEC-COL-05 | B6: Quick View Modal | C6: Overlay Pop-up Container | D6: Cho phép xem nhanh nồng độ hoạt chất và thông số sản phẩm mà không rời trang | E6: Modal popup: Gallery ảnh zoom, Tóm tắt công dụng, Bảng nồng độ hoạt chất, Dung tích tùy chọn (30ml, 50ml), Chọn số lượng, Nút Xem chi tiết | F6: Nhấn phím ESC để đóng modal; Trap focus bàn phím bên trong modal khi đang mở; Khóa cuộn trang nền body overflow: hidden | G6: layouts/partials/quick-view-modal.html | H6: P1 Usability: Không làm mất trạng thái lọc của trang danh mục khi đóng mở Quick View Modal | I6: Focus tự động quay lại nút kích hoạt sau khi đóng modal; Hoạt động trơn tru trên màn hình cảm ứng di động

Sheet Chi_Tiet_SanPham_PDP
A1: Section_ID | B1: Section_Name | C1: Layout_Hierarchy | D1: Business_Purpose | E1: Feature_Specifications | F1: Processing_Logic_Constraints | G1: Data_Source_Origin | H1: Agent_Audit_Rules (Meta-Skill V6.0) | I1: Agent_Refix_Acceptance_Criteria
A2: SEC-PDP-01 | B2: Product Hero & Purchasing Section | C2: Top Split (Trái 55%, Phải 45%) | D2: Trình diễn hình ảnh chi tiết và hỗ trợ quyết định mua hàng/đặt hàng chính hãng | E2: Gallery ảnh lớn kèm thumbnail; Zoom ảnh khi hover; Badge chứng nhận GSP; Tên, SKU, Thương hiệu, Nồng độ %, Giá niêm yết, Chọn dung tích, Nút Đặt Hàng & Tư Vấn | F2: Đồng bộ thumbnail với ảnh chính; Cập nhật giá động theo variants; Kiểm tra tồn kho trước khi kích hoạt nút đặt hàng | G2: content/products/*.md (Variants Frontmatter) | H2: P0 Legal: Bắt buộc hiển thị số tiếp nhận phiếu công bố mỹ phẩm chuẩn hóa theo quy định quản lý mỹ phẩm | I2: 100% ảnh zoom sắc nét; Thông tin phân loại dung tích hiển thị rõ ràng; Không lỗi giá 0đ hoặc giá trống
A3: SEC-PDP-02 | B3: Active Ingredients Science Table | C3: Middle Full Container | D3: Công bố minh bạch thành phần hoạt tính và cơ chế khoa học chuẩn da liễu | E3: Bảng chi tiết: Tên hoạt chất quốc tế (INCI), Nồng độ %, Độ pH sản phẩm, Nhóm công năng chính, Cơ chế sinh học tác động lên da | F3: Bảng hỗ trợ cuộn ngang trên di động có chỉ báo; Chú thích liên kết trực tiếp sang thư viện hoạt chất /ingredients/ | G3: content/products/*.md (ingredients metadata) | H3: P1 Integrity: Dữ liệu nồng độ % và pH phải lấy chuẩn 100% từ hồ sơ kỹ thuật NSX (COA), nghiêm cấm tự suy diễn nồng độ | I3: Bảng hiển thị responsive mượt mà; Chữ không bị tràn khung trên màn hình 360px
A4: SEC-PDP-03 | B4: 3 Clinical Decision Stories | C4: Middle Storytelling Container | D4: Cung cấp luận chứng lâm sàng thuyết phục theo khung GEO SEO & High-Conversion | E4: 3 Câu chuyện quyết định: (1) Tại sao Chuyên gia chọn hoạt chất này, (2) Khắc phục rào cản kích ứng da nhạy cảm ra sao, (3) Thực chứng lâm sàng tại cơ sở | F4: Cấu trúc Typography phân cấp rõ ràng (H3, trích dẫn chuyên môn chuyên gia, số liệu nghiên cứu cụ thể); Chuẩn AI crawling | G4: layouts/partials/decision-stories.html | H4: Zero Hallucination: Không sử dụng số liệu phần trăm ảo khi mẫu thử nhỏ (N < 30); Tránh các từ ngữ sáo rỗng vô căn cứ | I4: Cấu trúc thẻ HTML chuẩn ngữ nghĩa giúp AI Search Engines (Perplexity, ChatGPT, Gemini) dễ dàng trích xuất dữ liệu
A5: SEC-PDP-04 | B5: Usage Protocol & Contraindications | C5: Two-column Grid Container | D5: Hướng dẫn phác đồ sử dụng an toàn và cảnh báo chống chỉ định bắt buộc | E5: Cột trái: Phác đồ sáng/tối, thứ tự layer các bước; Cột phải: Chống chỉ định y khoa, lưu ý chống nắng, hiện tượng purging vs breakout | F5: Box cảnh báo chống chỉ định dùng tone màu vàng hổ phách y tế nổi bật; Thẻ icon cảnh báo rõ ràng | G5: content/products/*.md (usage & safety) | H5: P0 Medical Safety: Cảnh báo bắt buộc đối với phụ nữ mang thai nếu sản phẩm chứa Retinoids, Hydroquinone hoặc BHA nồng độ cao | I5: Đạt chuẩn cảnh báo an toàn y tế; Phân biệt rõ ràng giữa hướng dẫn thông thường và lưu ý bắt buộc
A6: SEC-PDP-05 | B6: Batch Verification & Storage Standards | C6: Accordion Full-width Container | D6: Minh bạch tiêu chuẩn lưu trữ kho GSP và hướng dẫn kiểm tra hàng thật | E6: Hướng dẫn quét mã QR tem chống giả Bộ Công An; Điều kiện bảo quản nhiệt độ chuẩn (15-25°C, độ ẩm < 70%); Hạn dùng sau mở nắp (PAO); Hotline tiếp nhận phản hồi | F6: Hiệu ứng toggle accordion đóng mở mượt mà; Chứa hotline tư vấn trực tiếp của Dược sĩ phụ trách chuyên môn | G6: data/storage_standards.yaml | H6: P0 Compliance: Minh bạch pháp nhân nhập khẩu và phân phối độc quyền tại Việt Nam theo Nghị định 43/2017/NĐ-CP về nhãn hàng hóa | I6: Accordion hỗ trợ bàn phím; Tải ảnh hướng dẫn quét tem rõ nét; Hotline dạng link bấm gọi điện được tel:...

Sheet Tra_Cuu_Hoat_Chat
A1: Section_ID | B1: Section_Name | C1: Layout_Hierarchy | D1: Business_Purpose | E1: Feature_Specifications | F1: Processing_Logic_Constraints | G1: Data_Source_Origin | H1: Agent_Audit_Rules (Meta-Skill V6.0) | I1: Agent_Refix_Acceptance_Criteria
A2: SEC-ING-01 | B2: Ingredients Search & Alphabet Filter | C2: Top Center Hero Container | D2: Tra cứu thành phần hoạt chất khoa học nhanh chóng cho Chuyên gia, Cố vấn và Khách hàng | E2: Thanh tìm kiếm realtime + Dải nút lọc theo bảng chữ cái A-Z; Dropdown lọc theo nhóm công năng (Trị mụn, Trị nám, Lão hóa, Phục hồi) | F2: Lọc tức thời danh sách bên dưới; Highlight từ khóa trùng khớp; Nhấn nút chữ cái cuộn mượt tới nhóm tương ứng | G2: data/ingredients_database.json | H2: P1 Accuracy: Dữ liệu tên quốc tế danh pháp INCI phải chuẩn hóa theo chuẩn Dược điển | I2: Tốc độ phản hồi tìm kiếm < 30ms; Hỗ trợ duyệt danh sách bằng phím Tab mượt mà
A3: SEC-ING-02 | B3: Scientific Ingredient Card Grid | C3: Main Grid (3 cột) | D3: Cung cấp hồ sơ khoa học chi tiết của từng hoạt chất dược mỹ phẩm | E3: Card có badge màu cảnh báo độ kích ứng (Xanh lá: Lành tính; Vàng: Cần làm quen; Đỏ: Chuyên sâu/Kích ứng cao); Click mở hồ sơ chi tiết | F3: Card có badge màu cảnh báo độ kích ứng (Xanh lá: Lành tính; Vàng: Cần làm quen; Đỏ: Kê đơn/Kích ứng cao); Click mở hồ sơ chi tiết | G3: content/ingredients/*.md | H3: P0 Compliance: Nồng độ giới hạn tối đa lưu hành phải tuân thủ nghiêm ngặt tiêu chuẩn an toàn mỹ phẩm ASEAN và hướng dẫn công bố | I3: Thẻ card hiển thị rõ ràng, phân cấp thị giác tốt; Badge màu sắc đạt độ tương phản chuẩn WCAG AA
A4: SEC-ING-03 | B4: Interaction & Combination Matrix | C4: Interactive Matrix Table | D4: Cẩm nang hướng dẫn phối hợp hoạt chất khoa học (Nên kết hợp vs Tuyệt đối tránh) | E4: Bảng ma trận 2 chiều: Xanh (Cộng hưởng tốt), Vàng (Thận trọng/Dãn cữ), Đỏ (Tuyệt đối không dùng chung cùng lúc kèm giải thích lý do vỡ pH/kích ứng) | F4: Bộ lọc tương tác giữa 2 hoạt chất bất kỳ do người dùng chọn từ 2 dropdown; Box giải thích cơ chế tương tác hóa học/sinh học cụ thể | G4: data/ingredient_matrix.json | H4: P0 Medical Safety: Cảnh báo nguy hiểm cấp độ đỏ khi phối hợp BHA/AHA nồng độ cao với Tretinoin hoặc Vitamin C nguyên chất L-AA | I4: Ma trận tương tác trực quan, dễ hiểu; Có trích dẫn nguồn tài liệu y khoa tham chiếu uy tín

Sheet Dai_Ly_B2B_Distribution
A1: Section_ID | B1: Section_Name | C1: Layout_Hierarchy | D1: Business_Purpose | E1: Feature_Specifications | F1: Processing_Logic_Constraints | G1: Data_Source_Origin | H1: Agent_Audit_Rules (Meta-Skill V6.0) | I1: Agent_Refix_Acceptance_Criteria
A2: SEC-B2B-01 | B2: B2B Partnership Hero | C2: Top Full Banner Container | D2: Giới thiệu chính sách hợp tác phân phối độc quyền cho Clinic, Spa, Nhà thuốc | E2: Quyền lợi đối tác: Mức chiết khấu hấp dẫn trực tiếp từ NSX, Chuyển giao phác đồ độc quyền, Hỗ trợ Marketing POSM; Nút Đăng Ký Đại Lý | F2: Banner tối ưu hóa tỷ lệ chuyển đổi CTA; Tải tài liệu Profile công ty dạng PDF | G2: layouts/b2b/hero.html | H2: P0 Legal: Thiết lập đối tác phân phối cho các cơ sở kinh doanh, nhà thuốc, spa có đăng ký kinh doanh và hồ sơ năng lực chuyên môn phù hợp | I2: Tỷ lệ chuyển đổi CTA cao; Văn phong chuyên nghiệp, chuẩn mực B2B
A3: SEC-B2B-02 | B3: 4-Tier Wholesale Discount Matrix | C3: Center Pricing Comparison Table | D3: Minh bạch các hạn mức nhập hàng, tỷ lệ chiết khấu và quyền lợi đồng hành | E3: Bảng so sánh 4 cấp bậc: Đại lý Bạc, Vàng, Kim Cương, Đối tác Chiến lược; Doanh số tối thiểu/tháng, % Chiết khấu, Thưởng quý, Đào tạo nhân sự, Hỗ trợ POSM | F3: Bảng so sánh responsive; Nổi bật gói được nhiều đối tác lựa chọn nhất; Chú thích điều khoản thanh toán công nợ minh bạch | G3: data/b2b_policy.yaml | H3: P1 Commercial Integrity: Tuân thủ quy chế kiểm soát giá bán lẻ niêm yết, nghiêm cấm các hành vi bán phá giá gây lũng đoạn thị trường | I3: Bảng định dạng rõ ràng, không gây hiểu nhầm; Có nút bấm chọn đăng ký tương ứng cho từng cấp bậc đại lý
A4: SEC-B2B-03 | B4: Document & Certification Repository | C4: Download Grid (3 cột) | D4: Cung cấp đầy đủ hồ sơ pháp lý công bố sản phẩm để phục vụ thanh kiểm tra thị trường | E4: Danh mục tệp tải về: Phiếu tiếp nhận công bố mỹ phẩm, Giấy chứng nhận lưu hành tự do (CFS), Kết quả kiểm nghiệm vi sinh (COA), Giấy ủy quyền phân phối | F4: Hiển thị dung lượng file và định dạng (PDF); Nút tải tài liệu; Chỉ cho phép đại lý đã đăng nhập xác thực tải các tài liệu kỹ thuật bảo mật | G4: static/documents/compliance/ | H4: P0 Compliance: Toàn bộ số phiếu tiếp nhận công bố phải tra cứu được trên hệ thống cơ sở dữ liệu công bố mỹ phẩm chuẩn hóa | I4: 100% link tải file hoạt động tốt, không có link 404; File PDF được ký số điện tử hợp lệ
A5: SEC-B2B-04 | B5: Partner Verification & Onboarding Form | C5: Bottom Form Container | D5: Thu thập và xác minh hồ sơ đại lý phân phối hoàn toàn tự động | E5: Form nhập liệu: Tên doanh nghiệp/cơ sở làm đẹp, Mã số thuế, Người đại diện, SĐT, Email, Địa chỉ kinh doanh, File đính kèm ĐKKD/Hồ sơ năng lực; Nút Hoàn Tất Đăng Ký | F5: Kiểm tra mã số thuế tự động qua API Tổng cục Thuế; Upload file chứng thực < 5MB (PDF/JPG); Tích hợp xác thực chống spam Turnstile/reCAPTCHA | G5: layouts/b2b/onboarding-form.html | H5: P0 Security: Áp dụng mã hóa HTTPS SSL; Tuân thủ Luật An ninh mạng và Luật Bảo vệ dữ liệu cá nhân 91/2025/QH15 trong lưu trữ thông tin B2B | I5: Form submit mượt mà; Tự động gửi email thông báo xác nhận tiếp nhận hồ sơ trong vòng 15 phút

Sheet Blog
A1: Section_ID | B1: Section_Name | C1: Layout_Hierarchy | D1: Business_Purpose | E1: Feature_Specifications | F1: Processing_Logic_Constraints | G1: Data_Source_Origin | H1: Agent_Audit_Rules (Meta-Skill V6.0) | I1: Agent_Refix_Acceptance_Criteria
A2: SEC-BLOG-01 | B2: Featured Medical Editorial Hero | C2: Hero Section (Full-width / Split banner) | D2: Làm nổi bật các chuyên đề lâm sàng, báo cáo nghiên cứu và bài viết biên tập bởi Chuyên gia da liễu | E2: Banner bài viết tiêu điểm: Ảnh thumbnail tỷ lệ 16:9 độ phân giải cao, Badge chuyên khoa (Da liễu, Dược lý, Lão hóa), Tiêu đề H1 chuẩn SEO, Tên Chuyên gia kiểm duyệt, Ngày đăng, Thời gian đọc ước tính | F2: Tự động xoay vòng top 3 bài viết ghim hoặc bài viết mới nhất được gắn tag Editorial_Pick; Click chuyển hướng sang trang chi tiết bài viết | G2: cms/articles/featured.json | H2: P0 Compliance: Tác giả và chuyên gia thẩm định (Reviewer) phải hiển thị đầy đủ thông tin chuyên môn (Thạc sĩ da liễu, Dược sĩ, Cố vấn thẩm mỹ) và kinh nghiệm thực nghiệm lâm sàng | I2: Tốc độ tải ảnh Hero đạt LCP < 1.2s; Badge chuyên khoa hiển thị màu sắc tương phản rõ nét
A3: SEC-BLOG-02 | B3: Medical Category & Topic Filter Bar | C3: Sticky Navigation Bar (Horizontal Scroll / Chips) | D3: Giúp người đọc và khách hàng phân loại, lọc nhanh kiến thức theo chủ đề chăm sóc da và liệu trình chuyên sâu | E3: Thanh cuộn ngang chứa danh mục: Tất cả, Mụn trứng cá, Nám & Tăng sắc tố, Phục hồi màng đáy, Trẻ hóa da, Chăm sóc sau liệu trình chuyên sâu; Ô tìm kiếm nhanh theo từ khóa tình trạng da | F3: Lọc động danh sách bài viết bên dưới theo Ajax/Realtime không tải lại trang; Lưu trạng thái lọc vào URL params (?topic=...); Highlight tab đang chọn | G3: api/v1/blog/categories | H3: P1 Accuracy: Các thuật ngữ chủ đề chăm sóc da phải dùng thuật ngữ khoa học chuẩn (vd: Trứng cá đỏ thay vì mụn đỏ; Viêm da cơ địa thay vì dị ứng thông thường) | I3: Thanh trượt chuyển tab phản hồi ngay lập tức < 50ms; Tương thích mượt mà trên thiết bị di động
A4: SEC-BLOG-03 | B4: Clinical Articles Masonry Grid | C4: Main Content Grid (3 cột Desktop / 1 cột Mobile) | D4: Hiển thị kho bài viết kiến thức chuyên sâu, case study chăm sóc thực tế và phác đồ phối hợp sản phẩm | E4: Card bài viết: Ảnh đại diện tối ưu WebP, Badge chuyên mục, Tiêu đề bài viết chuẩn khoa học, Đoạn trích dẫn tóm tắt (Excerpt tối đa 120 ký tự), Avatar và tên chuyên gia tác giả, Lượt xem, Nút Lưu bài viết | F4: Phân trang vô hạn (Infinite scroll) hoặc nút 'Tải thêm bài viết' (Load more); Lazy loading toàn bộ hình ảnh ngoài khung nhìn viewport | G4: api/v1/blog/posts?page=1&limit=9 | H4: P0 Scientific Ethics: Tuyệt đối không chứa tuyên bố phóng đại sai sự thật về hiệu quả; Bài viết có tài liệu tham khảo khoa học (PubMed/Dermatology Journals) | I4: Card hiển thị đồng đều về kích thước; Trích dẫn không vượt quá số dòng quy định; Nút tải thêm hoạt động trơn tru
A5: SEC-BLOG-04 | B5: Expert Consultation & Newsletter CTA | C5: Bottom Full-width Container | D5: Thu thập thông tin khách hàng tiềm năng nhận bản tin cập nhật kiến thức định kỳ và điều hướng đặt lịch tư vấn trực tiếp | E5: Box đăng ký nhận bản tin Dược mỹ phẩm qua Email; Banner kêu gọi 'Đặt lịch tư vấn cùng Chuyên gia da liễu' kèm nút CTA nổi bật | F5: Kiểm tra định dạng Email hợp lệ RFC 5322; Chống spam bằng reCAPTCHA v3 vô hình; Ghi nhận Lead trực tiếp vào hệ thống CRM | G5: services/lead_capture_form | H5: P1 Privacy: Tuân thủ quy định bảo mật dữ liệu thông tin cá nhân và chính sách riêng tư khách hàng (Nghị định 13/2023/NĐ-CP) | I5: Phản hồi thông báo đăng ký thành công bằng Toast message rõ ràng; Tỷ lệ chuyển đổi CTA tối ưu

Sheet Chi_Tiet_Blog
A1: Section_ID | B1: Section_Name | C1: Layout_Hierarchy | D1: Business_Purpose | E1: Feature_Specifications | F1: Processing_Logic_Constraints | G1: Data_Source_Origin | H1: Agent_Audit_Rules (Meta-Skill V6.0) | I1: Agent_Refix_Acceptance_Criteria
A2: SEC-BPOST-01 | B2: Article Header & Clinical Authority Metadata | C2: Top Hero Container | D2: Thiết lập uy tín khoa học, bản quyền chuyên môn và thông tin định danh bài viết khoa học | E2: Tiêu đề bài viết H1, Breadcrumb phân cấp đa tầng (Trang chủ > Blog > Chuyên đề), Badge thể loại, Ngày xuất bản & ngày cập nhật chuyên môn mới nhất, Tên Chuyên gia tác giả & Chuyên gia cố vấn bình duyệt (Peer-reviewed by) kèm liên kết hồ sơ chuyên gia, Nút chia sẻ mạng xã hội | F2: Tự động tính thời gian đọc dựa trên tổng số từ (200 từ/phút); Schema.org MedicalWebPage & Article chuẩn JSON-LD phục vụ SEO y tế | G2: cms/articles/detail_header.json | H2: P0 Author Verification: Mọi bài viết chuyên sâu phải có chữ ký số hoặc xác thực định danh của Chuyên gia da liễu có chứng nhận chuyên môn và kinh nghiệm thực tế | I2: Đầy đủ thẻ meta Open Graph và Schema markup; Hiển thị avatar và danh xưng chuyên môn của Chuyên gia rõ ràng
A3: SEC-BPOST-02 | B3: Medical Table of Contents & Sticky Anchor Nav | C3: Left Sidebar (Desktop Sticky) / Dropdown (Mobile) | D3: Giúp độc giả nắm bắt cấu trúc luận điểm khoa học và điều hướng nhanh đến mục nội dung cần đọc | E3: Mục lục tự động sinh (Auto Table of Contents) dựa trên các thẻ H2, H3 trong bài; Thanh chỉ báo tiến độ đọc (Reading progress bar) dạng line ở đầu trang | F3: Theo dõi vị trí cuộn trang (ScrollSpy) để active highlight mục lục tương ứng; Cuộn mượt (Smooth scroll) kèm bù trừ khoảng cách header sticky khi click anchor link | G3: script/client_scroll_spy.js | H3: P1 Usability: Không phát sinh hiện tượng che khuất tiêu đề mục tiêu khi cuộn tới vị trí neo | I3: Mục lục tự động ẩn trên màn hình nhỏ hoặc thu vào menu accordion linh hoạt; Trải nghiệm điều hướng mượt mà
A4: SEC-BPOST-03 | B4: Clinical Article Deep-Dive & Clinical Imagery | C4: Main Article Column (Max-width 780px) | D4: Trình bày nội dung chuyên sâu, cơ chế tác động sinh học, phác đồ chăm sóc và minh chứng lâm sàng | E4: Văn bản bài viết chuẩn Typography, Hộp trích dẫn nổi bật (Callout/Expert's Note), Hình ảnh so sánh Trước/Sau (Before/After Slider) có che bảo mật danh tính khách hàng, Infographic cơ chế hoạt động tế bào | F4: Bảo mật hình ảnh lâm sàng chống sao chép trái phép (Watermark bản quyền cơ sở/phòng lab); Hỗ trợ lightbox phóng to ảnh độ phân giải cao kèm chú thích chuyên môn | G4: cms/articles/body_content.md | H4: P1 Visual Standard: Hình ảnh lâm sàng Before/After bắt buộc phải có văn bản đồng thuận của khách hàng (Informed Consent) và làm mờ nhận diện khuôn mặt/mắt | I4: Nội dung bài viết mạch lạc, không lỗi font chữ, hình ảnh tối ưu dung lượng WebP tải nhanh dưới 1.5s
A5: SEC-BPOST-04 | B5: Referenced Products & Suggested Regimen | C5: Sticky Right Column / In-article Product Carousel | D5: Liên kết phác đồ chăm sóc trong bài viết tới danh mục dược mỹ phẩm chính hãng được khuyên dùng | E5: Thẻ sản phẩm liên quan: Ảnh sản phẩm GSP, Tên biệt dược/thương mại, Thành phần hoạt chất chính, Giá niêm yết B2C / Giá sỉ B2B (nếu đăng nhập đại lý), Nút 'Thêm vào giỏ' hoặc 'Cần tư vấn' | F5: Kiểm tra quyền hạn tài khoản (B2B vs B2C); Đối với sản phẩm hoạt chất nồng độ cao, kích hoạt cảnh báo 'Khuyên dùng có hướng dẫn của Chuyên gia' | G5: api/v1/products/linked_regimen | H5: P0 Safety Control: Khuyến cáo an toàn sử dụng đối với các hoạt chất điều trị chuyên sâu, cung cấp hướng dẫn chi tiết từ Chuyên gia da liễu | I5: Thẻ sản phẩm đồng bộ với hệ thống kho vận; Nút tương tác chuyển đổi trạng thái rõ ràng
A6: SEC-BPOST-05 | B6: Scientific References & Clinical Disclaimer | C6: Footer Article Container | D6: Đảm bảo tính minh bạch học thuật, trích dẫn nguồn nghiên cứu quốc tế và khuyến cáo sử dụng | E6: Danh sách tài liệu tham khảo đánh số có liên kết DOI/PubMed; Hộp khuyến cáo bắt buộc (Clinical Disclaimer: 'Thông tin mang tính chất phổ biến kiến thức khoa học, tham khảo ý kiến Chuyên gia trước khi áp dụng') | F6: Tự động kiểm tra tính khả dụng của link liên kết ngoài (external links); Mở link tài liệu tham khảo ở tab mới có rel='noopener noreferrer nofollow' | G6: cms/articles/references_disclaimer.json | H6: P0 Content Disclaimer: Hộp khuyến cáo tham khảo khoa học là quy chuẩn P0 bắt buộc để đảm bảo an toàn trải nghiệm khách hàng | I6: Tài liệu tham khảo đánh số chuẩn xác định dạng Vancouver; Hộp khuyến cáo hiển thị nổi bật với viền vàng cam cảnh báo

Sheet Dat_Lich_Hen
A1: Section_ID | B1: Section_Name | C1: Layout_Hierarchy | D1: Business_Purpose | E1: Feature_Specifications | F1: Processing_Logic_Constraints | G1: Data_Source_Origin | H1: Agent_Audit_Rules (Meta-Skill V6.0) | I1: Agent_Refix_Acceptance_Criteria
A2: SEC-APPT-01 | B2: Expert Profile & Specialty Selector | C2: Top Selection Container | D2: Giúp khách hàng lựa chọn Chuyên gia da liễu và dịch vụ tư vấn phù hợp nhu cầu | E2: Thẻ Chuyên gia: Ảnh chân dung chuyên nghiệp, Họ tên, Trình độ chuyên môn (Thạc sĩ, Dược sĩ, Cố vấn da liễu), Chuyên khoa thế mạnh (Trị mụn, Phục hồi da, Trẻ hóa, Cân bằng hệ vi sinh), Đánh giá rating 5 sao, Nơi công tác; Bộ lọc theo chi nhánh/cơ sở hoặc hình thức tư vấn (Trực tiếp tại cơ sở / Tư vấn từ xa Online) | F2: Truy xuất realtime lịch trống làm việc của Chuyên gia từ hệ thống điều phối; Khóa chọn Chuyên gia nếu đã kín lịch trong ngày | G2: api/v1/experts/schedule_availability | H2: P0 Expert Verification: 100% Chuyên gia tham gia tư vấn trực tuyến bắt buộc phải có hồ sơ năng lực chuyên môn và chứng nhận đào tạo chuyên sâu da liễu | I2: Giao diện chọn chuyên gia trực quan, hiển thị trạng thái 'Còn lịch' hoặc 'Hết lịch' rõ ràng theo thời gian thực
A3: SEC-APPT-02 | B3: Interactive Slot & Date Picker Calendar | C3: Main Calendar & Time Slot Matrix | D3: Cho phép khách hàng chủ động chọn ngày và khung giờ tư vấn linh hoạt theo thời gian thực | E3: Lịch chọn ngày trong tháng; Khung giờ chia theo slot 30 phút (Buổi sáng 8:30 - 12:00, Buổi chiều 13:30 - 17:30, Tối 18:00 - 20:00); Hiển thị trạng thái slot: Còn trống (Xanh), Đang giữ chỗ (Vàng), Đã đặt (Xám mờ) | F3: Cơ chế khóa tạm thời slot tư vấn (Lock slot trong 10 phút) khi khách hàng đang tiến hành điền thông tin; Tự động giải phóng slot nếu hết thời gian giữ chỗ mà không hoàn tất | G3: services/booking_slot_engine | H3: P0 Anti-Double-Booking: Cơ chế kiểm tra xung đột lịch (Concurrency check) ở mức Database Transaction, tuyệt đối không cho phép 2 khách hàng đặt trùng một khung giờ của cùng Chuyên gia | I3: Giao diện lịch mượt mà, phản hồi tức thì khi chọn ngày; Đếm ngược thời gian giữ chỗ hiển thị chuẩn xác
A4: SEC-APPT-03 | B4: Client Triage & Skin Intake Form | C4: Centered Two-Column Form Container | D4: Thu thập thông tin khách hàng, tiền sử chăm sóc, tình trạng da hiện tại và triệu chứng kích ứng sơ bộ | E4: Form nhập liệu: Họ tên khách hàng, Số điện thoại (xác thực OTP), Email liên hệ, Ngày sinh, Giới tính; Khảo sát tiền sử kích ứng mỹ phẩm, Tình trạng da đang gặp; Tải lên 3 ảnh chụp cận cảnh vùng da (Trước, Trái, Phải) | F4: Mã hóa dữ liệu cá nhân (AES-256); Validate chặt chẽ số điện thoại di động Việt Nam và định dạng ảnh tải lên (JPG/PNG < 5MB/ảnh) | G4: api/v1/clients/intake_submission | H4: P0 Data Privacy: Dữ liệu thông tin cá nhân và hình ảnh tình trạng da của khách hàng phải tuân thủ nghiêm ngặt quy định bảo mật theo Luật Bảo vệ dữ liệu cá nhân | I4: Thông báo lỗi validation cụ thể ở từng trường; Quy trình xác thực OTP SMS/Zalo ZNS nhanh chóng dưới 15s
A5: SEC-APPT-04 | B5: Booking Summary & Multi-channel Confirmation | C5: Bottom Confirmation & Success Modal | D5: Xác nhận chi tiết lịch hẹn, chi phí tư vấn và gửi thông báo xác nhận đa kênh cho khách hàng | E5: Bảng tóm tắt lịch hẹn: Tên Chuyên gia, Khung giờ & Ngày hẹn, Địa điểm/Link tư vấn online, Phí tư vấn (0đ nếu theo chương trình ưu đãi); Nút 'Xác nhận đặt lịch'; Modal thông báo thành công kèm mã QR Check-in tại quầy đón tiếp | F5: Gửi SMS/Zalo ZNS và Email tự động kèm file .ics để thêm sự kiện vào Google Calendar / Apple Calendar; Đồng bộ dữ liệu lịch hẹn về ứng dụng nội bộ của Chuyên gia | G5: services/notification_scheduler | H5: P1 Operational SLA: Tin nhắn xác nhận lịch hẹn và mã QR phải được gửi đến điện thoại khách hàng trong vòng tối đa 60 giây kể từ khi bấm xác nhận | I5: Mã QR Check-in sắc nét, dễ quét; File lịch .ics tích hợp đầy đủ thông tin địa chỉ và hướng dẫn chuẩn bị trước buổi tư vấn

Sheet Tra_Cuu_Don_Hang
A1: Section_ID | B1: Section_Name | C1: Layout_Hierarchy | D1: Business_Purpose | E1: Feature_Specifications | F1: Processing_Logic_Constraints | G1: Data_Source_Origin | H1: Agent_Audit_Rules (Meta-Skill V6.0) | I1: Agent_Refix_Acceptance_Criteria
A2: SEC-TRACK-01 | B2: Order Lookup & OTP Authentication Header | C2: Top Search Container | D2: Cho phép khách hàng và đại lý B2B tra cứu hành trình đơn hàng dược mỹ phẩm nhanh chóng, an toàn | E2: Thanh nhập: Mã đơn hàng (SO/DO-xxxx) hoặc Số điện thoại đặt hàng; Nút 'Tra cứu ngay'; Cơ chế gửi mã OTP xác thực số điện thoại để mở thông tin nhạy cảm của đơn hàng | F2: Validate cú pháp mã đơn hàng; Bắt buộc xác thực OTP để bảo vệ thông tin cá nhân và danh mục sản phẩm đi kèm; Giới hạn tần suất tra cứu (Rate limit 5 lần/phút/IP) chống crawl | G2: api/v1/orders/lookup_auth | H2: P0 Security & Privacy: Thông tin chi tiết khách hàng và đơn hàng dược mỹ phẩm chỉ được giải mã sau khi xác thực OTP thành công | I2: Phản hồi thông tin tra cứu tức thời < 100ms; Báo lỗi rõ ràng nếu mã đơn hàng hoặc số điện thoại không tồn tại
A3: SEC-TRACK-02 | B3: GSP Cold Chain & Milestone Timeline | C3: Main Stepper / Timeline Container | D3: Trực quan hóa lộ trình vận chuyển và kiểm soát nghiêm ngặt điều kiện nhiệt độ/độ ẩm chuẩn GSP/GDP y tế | E3: Dải timeline các mốc: Tiếp nhận đơn > Dược sĩ duyệt đơn > Đóng gói phòng sạch GSP > Đang vận chuyển bảo ôn > Đã giao hàng; Card thông số môi trường: Nhiệt độ kho/thùng xe bảo ôn (ví dụ: 15°C - 25°C hoặc 2°C - 8°C đối với Serum đặc trị sinh học), Độ ẩm không khí (< 60%) | F3: Tích hợp API thiết bị cảm biến IoT giám sát nhiệt độ thùng hàng theo thời gian thực; Cảnh báo màu đỏ nếu nhiệt độ vượt ngưỡng an toàn trong suốt hành trình | G3: services/iot_gsp_tracking | H3: P0 GSP Cold Chain Quality: Toàn bộ lô hàng dược mỹ phẩm điều trị bắt buộc phải lưu vết lịch sử nhiệt độ bảo quản chuẩn GSP từ kho tới tay khách hàng | I3: Thanh trạng thái hiển thị trực quan; Chỉ số nhiệt độ/độ ẩm cập nhật tự động từ log cảm biến xe lạnh vận tải y tế
A4: SEC-TRACK-03 | B4: Consignment Detail & Digital COA/VAT | C4: Bottom Two-Column Summary Container | D4: Cung cấp chi tiết kiện hàng, số lô hạn dùng, hóa đơn điện tử VAT và phiếu kiểm nghiệm COA chính hãng | E4: Danh sách sản phẩm chi tiết: Tên sản phẩm, Số lượng, Số lô sản xuất (Batch No.), Hạn sử dụng (Exp Date), Tem chống hàng giả QR; Nút tải file PDF Hóa đơn điện tử VAT và Phiếu kiểm nghiệm chất lượng (COA) của từng lô hàng | F4: Đồng bộ realtime với phần mềm ERP/WMS kho dược; Link tải COA/Hóa đơn có thời hạn an toàn (Signed URL 30 phút) | G4: api/v1/orders/consignment_details | H4: P1 Compliance: Số lô (Batch No.) và Hạn sử dụng trên phiếu xuất kho điện tử phải trùng khớp 100% với nhãn phụ in trên vỏ hộp thực tế | I4: Hỗ trợ tải chứng từ COA/VAT dạng PDF sắc nét; Hiển thị đầy đủ thông tin xuất xứ và cam kết chính hãng 100%
